{
 "cells": [
  {
   "cell_type": "code",
   "execution_count": 3,
   "id": "00815138-a093-4639-ac6b-a24782ac91f7",
   "metadata": {},
   "outputs": [],
   "source": [
    "import pandas as pd\n",
    "import numpy as np"
   ]
  },
  {
   "cell_type": "code",
   "execution_count": 4,
   "id": "5273817b-e352-4e85-9801-43790c7ef7b1",
   "metadata": {},
   "outputs": [
    {
     "name": "stdout",
     "output_type": "stream",
     "text": [
      "Unexpected exception formatting exception. Falling back to standard exception\n"
     ]
    },
    {
     "name": "stderr",
     "output_type": "stream",
     "text": [
      "Traceback (most recent call last):\n",
      "  File \"C:\\Users\\Woodzi\\AppData\\Local\\Packages\\PythonSoftwareFoundation.Python.3.9_qbz5n2kfra8p0\\LocalCache\\local-packages\\Python39\\site-packages\\IPython\\core\\interactiveshell.py\", line 3433, in run_code\n",
      "    exec(code_obj, self.user_global_ns, self.user_ns)\n",
      "  File \"C:\\Users\\Woodzi\\AppData\\Local\\Temp\\ipykernel_9376\\1337961540.py\", line 1, in <module>\n",
      "    df_lib = pd.read_csv('playlist.csv')\n",
      "  File \"C:\\Users\\Woodzi\\AppData\\Local\\Packages\\PythonSoftwareFoundation.Python.3.9_qbz5n2kfra8p0\\LocalCache\\local-packages\\Python39\\site-packages\\pandas\\util\\_decorators.py\", line 211, in wrapper\n",
      "    return func(*args, **kwargs)\n",
      "  File \"C:\\Users\\Woodzi\\AppData\\Local\\Packages\\PythonSoftwareFoundation.Python.3.9_qbz5n2kfra8p0\\LocalCache\\local-packages\\Python39\\site-packages\\pandas\\util\\_decorators.py\", line 331, in wrapper\n",
      "    return func(*args, **kwargs)\n",
      "  File \"C:\\Users\\Woodzi\\AppData\\Local\\Packages\\PythonSoftwareFoundation.Python.3.9_qbz5n2kfra8p0\\LocalCache\\local-packages\\Python39\\site-packages\\pandas\\io\\parsers\\readers.py\", line 950, in read_csv\n",
      "    return _read(filepath_or_buffer, kwds)\n",
      "  File \"C:\\Users\\Woodzi\\AppData\\Local\\Packages\\PythonSoftwareFoundation.Python.3.9_qbz5n2kfra8p0\\LocalCache\\local-packages\\Python39\\site-packages\\pandas\\io\\parsers\\readers.py\", line 611, in _read\n",
      "    return parser.read(nrows)\n",
      "  File \"C:\\Users\\Woodzi\\AppData\\Local\\Packages\\PythonSoftwareFoundation.Python.3.9_qbz5n2kfra8p0\\LocalCache\\local-packages\\Python39\\site-packages\\pandas\\io\\parsers\\readers.py\", line 1778, in read\n",
      "    ) = self._engine.read(  # type: ignore[attr-defined]\n",
      "  File \"C:\\Users\\Woodzi\\AppData\\Local\\Packages\\PythonSoftwareFoundation.Python.3.9_qbz5n2kfra8p0\\LocalCache\\local-packages\\Python39\\site-packages\\pandas\\io\\parsers\\c_parser_wrapper.py\", line 230, in read\n",
      "    chunks = self._reader.read_low_memory(nrows)\n",
      "  File \"pandas\\_libs\\parsers.pyx\", line 808, in pandas._libs.parsers.TextReader.read_low_memory\n",
      "  File \"pandas\\_libs\\parsers.pyx\", line 866, in pandas._libs.parsers.TextReader._read_rows\n",
      "  File \"pandas\\_libs\\parsers.pyx\", line 852, in pandas._libs.parsers.TextReader._tokenize_rows\n",
      "  File \"pandas\\_libs\\parsers.pyx\", line 1973, in pandas._libs.parsers.raise_parser_error\n",
      "pandas.errors.ParserError: Error tokenizing data. C error: Expected 12 fields in line 3, saw 13\n",
      "\n",
      "\n",
      "During handling of the above exception, another exception occurred:\n",
      "\n",
      "Traceback (most recent call last):\n",
      "  File \"C:\\Users\\Woodzi\\AppData\\Local\\Packages\\PythonSoftwareFoundation.Python.3.9_qbz5n2kfra8p0\\LocalCache\\local-packages\\Python39\\site-packages\\IPython\\core\\interactiveshell.py\", line 2052, in showtraceback\n",
      "    stb = self.InteractiveTB.structured_traceback(\n",
      "  File \"C:\\Users\\Woodzi\\AppData\\Local\\Packages\\PythonSoftwareFoundation.Python.3.9_qbz5n2kfra8p0\\LocalCache\\local-packages\\Python39\\site-packages\\IPython\\core\\ultratb.py\", line 1118, in structured_traceback\n",
      "    return FormattedTB.structured_traceback(\n",
      "  File \"C:\\Users\\Woodzi\\AppData\\Local\\Packages\\PythonSoftwareFoundation.Python.3.9_qbz5n2kfra8p0\\LocalCache\\local-packages\\Python39\\site-packages\\IPython\\core\\ultratb.py\", line 1012, in structured_traceback\n",
      "    return VerboseTB.structured_traceback(\n",
      "  File \"C:\\Users\\Woodzi\\AppData\\Local\\Packages\\PythonSoftwareFoundation.Python.3.9_qbz5n2kfra8p0\\LocalCache\\local-packages\\Python39\\site-packages\\IPython\\core\\ultratb.py\", line 865, in structured_traceback\n",
      "    formatted_exception = self.format_exception_as_a_whole(etype, evalue, etb, number_of_lines_of_context,\n",
      "  File \"C:\\Users\\Woodzi\\AppData\\Local\\Packages\\PythonSoftwareFoundation.Python.3.9_qbz5n2kfra8p0\\LocalCache\\local-packages\\Python39\\site-packages\\IPython\\core\\ultratb.py\", line 818, in format_exception_as_a_whole\n",
      "    frames.append(self.format_record(r))\n",
      "  File \"C:\\Users\\Woodzi\\AppData\\Local\\Packages\\PythonSoftwareFoundation.Python.3.9_qbz5n2kfra8p0\\LocalCache\\local-packages\\Python39\\site-packages\\IPython\\core\\ultratb.py\", line 736, in format_record\n",
      "    result += ''.join(_format_traceback_lines(frame_info.lines, Colors, self.has_colors, lvals))\n",
      "  File \"C:\\Users\\Woodzi\\AppData\\Local\\Packages\\PythonSoftwareFoundation.Python.3.9_qbz5n2kfra8p0\\LocalCache\\local-packages\\Python39\\site-packages\\stack_data\\utils.py\", line 144, in cached_property_wrapper\n",
      "    value = obj.__dict__[self.func.__name__] = self.func(obj)\n",
      "  File \"C:\\Users\\Woodzi\\AppData\\Local\\Packages\\PythonSoftwareFoundation.Python.3.9_qbz5n2kfra8p0\\LocalCache\\local-packages\\Python39\\site-packages\\stack_data\\core.py\", line 734, in lines\n",
      "    pieces = self.included_pieces\n",
      "  File \"C:\\Users\\Woodzi\\AppData\\Local\\Packages\\PythonSoftwareFoundation.Python.3.9_qbz5n2kfra8p0\\LocalCache\\local-packages\\Python39\\site-packages\\stack_data\\utils.py\", line 144, in cached_property_wrapper\n",
      "    value = obj.__dict__[self.func.__name__] = self.func(obj)\n",
      "  File \"C:\\Users\\Woodzi\\AppData\\Local\\Packages\\PythonSoftwareFoundation.Python.3.9_qbz5n2kfra8p0\\LocalCache\\local-packages\\Python39\\site-packages\\stack_data\\core.py\", line 677, in included_pieces\n",
      "    scope_pieces = self.scope_pieces\n",
      "  File \"C:\\Users\\Woodzi\\AppData\\Local\\Packages\\PythonSoftwareFoundation.Python.3.9_qbz5n2kfra8p0\\LocalCache\\local-packages\\Python39\\site-packages\\stack_data\\utils.py\", line 144, in cached_property_wrapper\n",
      "    value = obj.__dict__[self.func.__name__] = self.func(obj)\n",
      "  File \"C:\\Users\\Woodzi\\AppData\\Local\\Packages\\PythonSoftwareFoundation.Python.3.9_qbz5n2kfra8p0\\LocalCache\\local-packages\\Python39\\site-packages\\stack_data\\core.py\", line 614, in scope_pieces\n",
      "    scope_start, scope_end = self.source.line_range(self.scope)\n",
      "  File \"C:\\Users\\Woodzi\\AppData\\Local\\Packages\\PythonSoftwareFoundation.Python.3.9_qbz5n2kfra8p0\\LocalCache\\local-packages\\Python39\\site-packages\\stack_data\\core.py\", line 178, in line_range\n",
      "    return line_range(self.asttext(), node)\n",
      "  File \"C:\\Users\\Woodzi\\AppData\\Local\\Packages\\PythonSoftwareFoundation.Python.3.9_qbz5n2kfra8p0\\LocalCache\\local-packages\\Python39\\site-packages\\executing\\executing.py\", line 428, in asttext\n",
      "    self._asttext = ASTText(self.text, tree=self.tree, filename=self.filename)\n",
      "  File \"C:\\Users\\Woodzi\\AppData\\Local\\Packages\\PythonSoftwareFoundation.Python.3.9_qbz5n2kfra8p0\\LocalCache\\local-packages\\Python39\\site-packages\\asttokens\\asttokens.py\", line 307, in __init__\n",
      "    super(ASTText, self).__init__(source_text, filename)\n",
      "  File \"C:\\Users\\Woodzi\\AppData\\Local\\Packages\\PythonSoftwareFoundation.Python.3.9_qbz5n2kfra8p0\\LocalCache\\local-packages\\Python39\\site-packages\\asttokens\\asttokens.py\", line 44, in __init__\n",
      "    source_text = six.ensure_text(source_text)\n",
      "AttributeError: module 'six' has no attribute 'ensure_text'\n"
     ]
    }
   ],
   "source": [
    "df_lib = pd.read_csv('playlist.csv')"
   ]
  },
  {
   "cell_type": "code",
   "execution_count": null,
   "id": "97b3c8db-66b7-405c-9d1b-ee0e3be864c0",
   "metadata": {},
   "outputs": [],
   "source": []
  }
 ],
 "metadata": {
  "kernelspec": {
   "display_name": "Python 3 (ipykernel)",
   "language": "python",
   "name": "python3"
  },
  "language_info": {
   "codemirror_mode": {
    "name": "ipython",
    "version": 3
   },
   "file_extension": ".py",
   "mimetype": "text/x-python",
   "name": "python",
   "nbconvert_exporter": "python",
   "pygments_lexer": "ipython3",
   "version": "3.9.13"
  }
 },
 "nbformat": 4,
 "nbformat_minor": 5
}
